Workbook

Sheet Raw Dataset
A1: India Export Statistics-APEDA Major Products
A3: Year: 2026-27,2025-26,2023-24
A4: State: All
A5: Port: All
A6: Country: All
A7: Product: Agri Products (APEDA Only)
D8: Value In USD Million | G8: Quantity In MT
A9: State | B9: Port | C9: Products | D9: 2023-24 | E9: 2025-26 | F9: 2026-27 (April-July) | G9: 2023-24 | H9: 2025-26 | I9: 2026-27 (April-July) | J9: Countryname
A10: Total | D10: 25168.06 | E10: 28898.61 | F10: 10149.89 | G10: 30820560 | H10: 38151878 | I10: 13174293
A11: Gujarat | B11: MUNDRA SEA | C11: BASMATI RICE | D11: 2169.99 | E11: 2298.45 | F11: 830.81 | G11: 1998793.1 | H11: 2690097.6 | I11: 902322.53 | J11: world
A12: Maharashtra | B12: NHAVA SHEVA SEA | C12: BUFFALO MEAT | D12: 917.88 | E12: 1496.37 | F12: 562.28 | G12: 318733.64 | H12: 425067.48 | I12: 130651.44 | J12: world
A13: Uttar Pradesh | B13: CFS ALBATROSS/ICD DADRI | C13: BUFFALO MEAT | D13: 936.57 | E13: 1048.66 | F13: 544.64 | G13: 324888.7 | H13: 290388.47 | I13: 124459.18 | J13: world
A14: Andhra Pradesh | B14: KAKINADA SEA | C14: NON BASMATI RICE | D14: 1019.88 | E14: 1359.84 | F14: 419.33 | G14: 2589020.7 | H14: 3778728.5 | I14: 1296925.5 | J14: world
A15: Gujarat | B15: KANDLA SEA SEA | C15: BASMATI RICE | D15: 1242.07 | E15: 1187.45 | F15: 389.9 | G15: 1177950.2 | H15: 1481392.6 | I15: 427258.73 | J15: world
A16: Andhra Pradesh | B16: VISAKHAPATNAM SEA | C16: NON BASMATI RICE | D16: 667.67 | E16: 612.51 | F16: 250.94 | G16: 1654430.7 | H16: 1690603.5 | I16: 774317.55 | J16: world
A17: Gujarat | B17: MUNDRA SEA | C17: NON BASMATI RICE | D17: 730.01 | E17: 693.36 | F17: 248.56 | G17: 1736946.5 | H17: 1507924.4 | I17: 563528.33 | J17: world
A18: Uttar Pradesh | B18: ICD CGML DADRI | C18: BUFFALO MEAT | D18: 358.89 | E18: 532.99 | F18: 222.25 | G18: 123625.07 | H18: 147257.68 | I18: 50127.91 | J18: world
A19: Gujarat | B19: KANDLA SEA SEA | C19: NON BASMATI RICE | D19: 257.12 | E19: 582.61 | F19: 206.94 | G19: 667453.21 | H19: 1527054.1 | I19: 578738.97 | J19: world
A20: West Bengal | B20: KOLKATA SEA | C20: NON BASMATI RICE | D20: 396.23 | E20: 456.93 | F20: 184.12 | G20: 943947.01 | H20: 1244058.8 | I20: 560583.15 | J20: world
A21: Gujarat | B21: MUNDRA SEA | C21: PULSES | D21: 176.05 | E21: 385.68 | F21: 183.38 | G21: 135676.5 | H21: 394735.21 | I21: 185043.86 | J21: world
A22: Maharashtra | B22: NHAVA SHEVA SEA | C22: NON BASMATI RICE | D22: 257.82 | E22: 464.19 | F22: 178.79 | G22: 634642.31 | H22: 1152704.9 | I22: 457683.02 | J22: world
... A3298: Tamil Nadu | B3298: ICD HOSUR Tamilnadu | C3298: OTHER FRESH FRUITS | D3298: 0.06 | E3298: 0.05 | F3298: 0 | G3298: 55.78 | H3298: 37.53 | I3298: 0 | J3298: world
A3299: Source: DGCIS

Sheet Cleaned Dataset
A1: State | B1: Region | C1: Port | D1: Port Type | E1: Product | F1: Product Category | G1: 2023-24 Value (USD Mn) | H1: 2025-26 Value (USD Mn) | I1: 2026-27 Apr-Jul Value (USD Mn) | J1: 2023-24 Qty (MT) | K1: 2025-26 Qty (MT) | L1: 2026-27 Apr-Jul Qty (MT) | M1: Value Change 2025-26 vs 2023-24 | N1: Qty Change 2025-26 vs 2023-24 | O1: 2026-27 Value Change | P1: Countryname
A2: Gujarat | B2: =INDEX(State_Region!$B$2:$B$26,MATCH(TRIM(A2),State_Region!$A$2:$A$26,0)) -> West | C2: MUNDRA SEA | D2: =INDEX(Port_Type!$B$2:$B$227,MATCH(TRIM(C2),Port_Type!$A$2:$A$227,0)) -> Sea Port | E2: BASMATI RICE | F2: =INDEX(Product_Category!$B$2:$B$45,MATCH(TRIM(E2),Product_Category!$A$2:$A$45,0)) -> Cereals & Grains | G2: 2169.99 | H2: 2298.45 | I2: 830.81 | J2: 1998793.1 | K2: 2690097.6 | L2: 902322.53 | M2: =H2-G2 -> 128.46 | N2: =K2-J2 -> 691304.43 | O2: =I2-H2 -> -1467.64 | P2: India
A3: Maharashtra | B3: =INDEX(State_Region!$B$2:$B$26,MATCH(TRIM(A3),State_Region!$A$2:$A$26,0)) -> West | C3: NHAVA SHEVA SEA | D3: =INDEX(Port_Type!$B$2:$B$227,MATCH(TRIM(C3),Port_Type!$A$2:$A$227,0)) -> Sea Port | E3: BUFFALO MEAT | F3: =INDEX(Product_Category!$B$2:$B$45,MATCH(TRIM(E3),Product_Category!$A$2:$A$45,0)) -> Meat & Animal Products | G3: 917.88 | H3: 1496.37 | I3: 562.28 | J3: 318733.64 | K3: 425067.48 | L3: 130651.44 | M3: =H3-G3 -> 578.49 | N3: =K3-J3 -> 106333.84 | O3: =I3-H3 -> -934.09 | P3: India
A4: Uttar Pradesh | B4: =INDEX(State_Region!$B$2:$B$26,MATCH(TRIM(A4),State_Region!$A$2:$A$26,0)) -> North | C4: CFS ALBATROSS/ICD DADRI | D4: =INDEX(Port_Type!$B$2:$B$227,MATCH(TRIM(C4),Port_Type!$A$2:$A$227,0)) -> Inland ICD / CFS | E4: BUFFALO MEAT | F4: =INDEX(Product_Category!$B$2:$B$45,MATCH(TRIM(E4),Product_Category!$A$2:$A$45,0)) -> Meat & Animal Products | G4: 936.57 | H4: 1048.66 | I4: 544.64 | J4: 324888.7 | K4: 290388.47 | L4: 124459.18 | M4: =H4-G4 -> 112.09 | N4: =K4-J4 -> -34500.23 | O4: =I4-H4 -> -504.02 | P4: India
A5: Andhra Pradesh | B5: =INDEX(State_Region!$B$2:$B$26,MATCH(TRIM(A5),State_Region!$A$2:$A$26,0)) -> South | C5: KAKINADA SEA | D5: =INDEX(Port_Type!$B$2:$B$227,MATCH(TRIM(C5),Port_Type!$A$2:$A$227,0)) -> Sea Port | E5: NON BASMATI RICE | F5: =INDEX(Product_Category!$B$2:$B$45,MATCH(TRIM(E5),Product_Category!$A$2:$A$45,0)) -> Cereals & Grains | G5: 1019.88 | H5: 1359.84 | I5: 419.33 | J5: 2589020.7 | K5: 3778728.5 | L5: 1296925.5 | M5: =H5-G5 -> 339.96 | N5: =K5-J5 -> 1189707.8 | O5: =I5-H5 -> -940.51 | P5: India
A6: Gujarat | B6: =INDEX(State_Region!$B$2:$B$26,MATCH(TRIM(A6),State_Region!$A$2:$A$26,0)) -> West | C6: KANDLA SEA SEA | D6: =INDEX(Port_Type!$B$2:$B$227,MATCH(TRIM(C6),Port_Type!$A$2:$A$227,0)) -> Sea Port | E6: BASMATI RICE | F6: =INDEX(Product_Category!$B$2:$B$45,MATCH(TRIM(E6),Product_Category!$A$2:$A$45,0)) -> Cereals & Grains | G6: 1242.07 | H6: 1187.45 | I6: 389.9 | J6: 1177950.2 | K6: 1481392.6 | L6: 427258.73 | M6: =H6-G6 -> -54.62 | N6: =K6-J6 -> 303442.39 | O6: =I6-H6 -> -797.55 | P6: India
A7: Andhra Pradesh | B7: =INDEX(State_Region!$B$2:$B$26,MATCH(TRIM(A7),State_Region!$A$2:$A$26,0)) -> South | C7: VISAKHAPATNAM SEA | D7: =INDEX(Port_Type!$B$2:$B$227,MATCH(TRIM(C7),Port_Type!$A$2:$A$227,0)) -> Sea Port | E7: NON BASMATI RICE | F7: =INDEX(Product_Category!$B$2:$B$45,MATCH(TRIM(E7),Product_Category!$A$2:$A$45,0)) -> Cereals & Grains | G7: 667.67 | H7: 612.51 | I7: 250.94 | J7: 1654430.7 | K7: 1690603.5 | L7: 774317.55 | M7: =H7-G7 -> -55.16 | N7: =K7-J7 -> 36172.79 | O7: =I7-H7 -> -361.57 | P7: India
A8: Gujarat | B8: =INDEX(State_Region!$B$2:$B$26,MATCH(TRIM(A8),State_Region!$A$2:$A$26,0)) -> West | C8: MUNDRA SEA | D8: =INDEX(Port_Type!$B$2:$B$227,MATCH(TRIM(C8),Port_Type!$A$2:$A$227,0)) -> Sea Port | E8: NON BASMATI RICE | F8: =INDEX(Product_Category!$B$2:$B$45,MATCH(TRIM(E8),Product_Category!$A$2:$A$45,0)) -> Cereals & Grains | G8: 730.01 | H8: 693.36 | I8: 248.56 | J8: 1736946.5 | K8: 1507924.4 | L8: 563528.33 | M8: =H8-G8 -> -36.65 | N8: =K8-J8 -> -229022.04 | O8: =I8-H8 -> -444.8 | P8: India
A9: Uttar Pradesh | B9: =INDEX(State_Region!$B$2:$B$26,MATCH(TRIM(A9),State_Region!$A$2:$A$26,0)) -> North | C9: ICD CGML DADRI | D9: =INDEX(Port_Type!$B$2:$B$227,MATCH(TRIM(C9),Port_Type!$A$2:$A$227,0)) -> Inland ICD / CFS | E9: BUFFALO MEAT | F9: =INDEX(Product_Category!$B$2:$B$45,MATCH(TRIM(E9),Product_Category!$A$2:$A$45,0)) -> Meat & Animal Products | G9: 358.89 | H9: 532.99 | I9: 222.25 | J9: 123625.07 | K9: 147257.68 | L9: 50127.91 | M9: =H9-G9 -> 174.1 | N9: =K9-J9 -> 23632.61 | O9: =I9-H9 -> -310.74 | P9: India
A10: Gujarat | B10: =INDEX(State_Region!$B$2:$B$26,MATCH(TRIM(A10),State_Region!$A$2:$A$26,0)) -> West | C10: KANDLA SEA SEA | D10: =INDEX(Port_Type!$B$2:$B$227,MATCH(TRIM(C10),Port_Type!$A$2:$A$227,0)) -> Sea Port | E10: NON BASMATI RICE | F10: =INDEX(Product_Category!$B$2:$B$45,MATCH(TRIM(E10),Product_Category!$A$2:$A$45,0)) -> Cereals & Grains | G10: 257.12 | H10: 582.61 | I10: 206.94 | J10: 667453.21 | K10: 1527054.1 | L10: 578738.97 | M10: =H10-G10 -> 325.49 | N10: =K10-J10 -> 859600.93 | O10: =I10-H10 -> -375.67 | P10: India
A11: West Bengal | B11: =INDEX(State_Region!$B$2:$B$26,MATCH(TRIM(A11),State_Region!$A$2:$A$26,0)) -> East | C11: KOLKATA SEA | D11: =INDEX(Port_Type!$B$2:$B$227,MATCH(TRIM(C11),Port_Type!$A$2:$A$227,0)) -> Sea Port | E11: NON BASMATI RICE | F11: =INDEX(Product_Category!$B$2:$B$45,MATCH(TRIM(E11),Product_Category!$A$2:$A$45,0)) -> Cereals & Grains | G11: 396.23 | H11: 456.93 | I11: 184.12 | J11: 943947.01 | K11: 1244058.8 | L11: 560583.15 | M11: =H11-G11 -> 60.7 | N11: =K11-J11 -> 300111.78 | O11: =I11-H11 -> -272.81 | P11: India
A12: Gujarat | B12: =INDEX(State_Region!$B$2:$B$26,MATCH(TRIM(A12),State_Region!$A$2:$A$26,0)) -> West | C12: MUNDRA SEA | D12: =INDEX(Port_Type!$B$2:$B$227,MATCH(TRIM(C12),Port_Type!$A$2:$A$227,0)) -> Sea Port | E12: PULSES | F12: =INDEX(Product_Category!$B$2:$B$45,MATCH(TRIM(E12),Product_Category!$A$2:$A$45,0)) -> Pulses | G12: 176.05 | H12: 385.68 | I12: 183.38 | J12: 135676.5 | K12: 394735.21 | L12: 185043.86 | M12: =H12-G12 -> 209.63 | N12: =K12-J12 -> 259058.71 | O12: =I12-H12 -> -202.3 | P12: India
A13: Maharashtra | B13: =INDEX(State_Region!$B$2:$B$26,MATCH(TRIM(A13),State_Region!$A$2:$A$26,0)) -> West | C13: NHAVA SHEVA SEA | D13: =INDEX(Port_Type!$B$2:$B$227,MATCH(TRIM(C13),Port_Type!$A$2:$A$227,0)) -> Sea Port | E13: NON BASMATI RICE | F13: =INDEX(Product_Category!$B$2:$B$45,MATCH(TRIM(E13),Product_Category!$A$2:$A$45,0)) -> Cereals & Grains | G13: 257.82 | H13: 464.19 | I13: 178.79 | J13: 634642.31 | K13: 1152704.9 | L13: 457683.02 | M13: =H13-G13 -> 206.37 | N13: =K13-J13 -> 518062.54 | O13: =I13-H13 -> -285.4 | P13: India
... A3289: Tamil Nadu | B3289: =INDEX(State_Region!$B$2:$B$26,MATCH(TRIM(A3289),State_Region!$A$2:$A$26,0)) -> South | C3289: ICD HOSUR Tamilnadu | D3289: =INDEX(Port_Type!$B$2:$B$227,MATCH(TRIM(C3289),Port_Type!$A$2:$A$227,0)) -> Inland ICD / CFS | E3289: OTHER FRESH FRUITS | F3289: =INDEX(Product_Category!$B$2:$B$45,MATCH(TRIM(E3289),Product_Category!$A$2:$A$45,0)) -> Fresh Fruits & Vegetables | G3289: 0.06 | H3289: 0.05 | I3289: 0 | J3289: 55.78 | K3289: 37.53 | L3289: 0 | M3289: =H3289-G3289 -> -0.01 | N3289: =K3289-J3289 -> -18.25 | O3289: =I3289-H3289 -> -0.05 | P3289: India

Sheet State_Region
A1: State | B1: Region
A2: Andhra Pradesh | B2: South
A3: Assam | B3: North-East
A4: Bihar | B4: East
A5: Chhattisgarh | B5: Central
A6: Delhi | B6: North
A7: Goa | B7: West
A8: Gujarat | B8: West
A9: Haryana | B9: North
A10: Himachal Pradesh | B10: North
A11: Karnataka | B11: South
A12: Kerala | B12: South
... A26: West Bengal | B26: East

Sheet Product_Category
A1: Product | B1: Product Category
A2: ALBUMIN( Eggs & Milk ) | B2: Dairy, Poultry & Honey
A3: ALCOHOLIC BEVERAGES | B3: Processed Foods
A4: ANIMAL CASINGS | B4: Meat & Animal Products
A5: BASMATI RICE | B5: Cereals & Grains
A6: BUFFALO MEAT | B6: Meat & Animal Products
A7: CASEIN | B7: Dairy, Poultry & Honey
A8: CEREAL PREPARATIONS | B8: Processed Foods
A9: COCOA PRODUCTS | B9: Processed Foods
A10: CUCUMBER AND GHERKINS( PREPD. & PRESVD) | B10: Processed Foods
A11: Cashew Kernel | B11: Nuts & Oilseeds
A12: Cashew Nuts Fresh/Dried In Shell | B12: Nuts & Oilseeds
... A45: WHEAT | B45: Cereals & Grains

Sheet Port_Type
A1: Port | B1: Port Type
A2: ACC AMRITSAR (RAJASANSI) Punjab | B2: Air Cargo
A3: ACC CALICUT, KARIPUR Airport | B3: Air Cargo
A4: ACC COIMBATORE AIRPORT | B4: Air Cargo
A5: ACC GOA,DABOLIM Airport | B5: Air Cargo
A6: ACC JANORI (NASIK) SEA | B6: Air Cargo
A7: ACC MOPA, GOA | B7: Air Cargo
A8: ADANI ICD KILA RAIPUR LUDHIANA | B8: Inland ICD / CFS
A9: AGARTALA ROAD/ RAILWAY | B9: Land Border / Rail
A10: AHMEDABAD AIR CARGO COMPLEX | B10: Air Cargo
A11: AIR CARGO TRICHI Tamilnadu | B11: Air Cargo
A12: AP Industrial Infra Ltd PH SEZ | B12: SEZ / EPZ
... A227: VIZHINJAM INTL SEAPORT ADANI SEA | B227: Sea Port

Sheet Pivot_Region
A1: Pivot_Region
A2: Row Labels | B2: Sum of 2023-24 Value (USD Mn) | C2: Sum of 2025-26 Value (USD Mn)
A3: Central | B3: 318.15 | C3: 417.74
A4: Chhattisgarh | B4: 34.37 | C4: 8.35
A5: ICD RAIPUR | B5: 34.37 | C5: 8.35
A6: Madhya Pradesh | B6: 283.78 | C6: 409.39
A7: ICD DHANNAD | B7: 5.86 | C7: 7.4
A8: ICD KHEDA | B8: 1.75 | C8: 23.33
A9: ICD MALANPUR | B9: 36.51 | C9: 87.81
A10: ICD MANDIDEEP | B10: 193.29 | C10: 190.05
A11: ICD PITHAMPUR (INDORE) | B11: 43.32 | C11: 35.96
A12: ICD POWARKHEDA Madhya Pradesh | B12: 0 | C12: 62.25
A13: INDORE AIRPORT | B13: 1.92 | C13: 1.74
A14: SEZ Indore | B14: 1.13 | C14: 0.85
... A260: Grand Total | B260: 25167.73 | C260: 28898.07

Sheet pivot tables
A1: Pivot_Product | E1: Pivot_Category
A2: Row Labels | B2: Sum of 2025-26 Value (USD Mn) | E2: Row Labels | F2: Sum of 2025-26 Value (USD Mn) | G2: Sum of 2023-24 Value (USD Mn) | H2: % 2025-26 Value (USD Mn)2
A3: Cereals & Grains | B3: 12185.98 | E3: Cereals & Grains | F3: 12185.98 | G3: 11156.87 | H3: 0.42168837
A4: BASMATI RICE | B4: 5672.91 | E4: Dairy, Poultry & Honey | F4: 974.34 | G4: 673.9 | H4: 0.033716439
A5: MAIZE | B5: 374.77 | E5: Fresh Fruits & Vegetables | F5: 1904.89 | G5: 1762.05 | H5: 0.065917551
A6: MILLED PRODUCTS | B6: 178.57 | E6: Meat & Animal Products | F6: 5262.74 | G6: 3869.93 | H6: 0.18211389
A7: Millet | B7: 61.57 | E7: Nuts & Oilseeds | F7: 1129.89 | G7: 1233.94 | H7: 0.039099151
A8: NON BASMATI RICE | B8: 5864.41 | E8: Others | F8: 850.31 | G8: 847.56 | H8: 0.029424456
A9: OTHER CEREALS | B9: 23.47 | E9: Processed Foods | F9: 5620.38 | G9: 4936.55 | H9: 0.19448981
A10: WHEAT | B10: 10.28 | E10: Pulses | F10: 969.54 | G10: 686.93 | H10: 0.033550337
A11: Dairy, Poultry & Honey | B11: 974.34 | E11: Grand Total | F11: 28898.07 | G11: 25167.73 | H11: 1
A12: ALBUMIN( Eggs & Milk ) | B12: 22.93
A13: CASEIN | B13: 18.45 | E13: Pivot_PortType | I13: Pivot_Port
A14: DAIRY PRODUCTS | B14: 407.18 | E14: Row Labels | F14: Sum of 2025-26 Value (USD Mn) | G14: %2025-26 Value (USD Mn)2 | I14: Row Labels | J14: Sum of 2025-26 Value (USD Mn)
A15: Egg and Live Birds (Poultry) | B15: 214.1 | E15: Air Cargo | F15: 677.21 | G15: 0.023434437 | I15: CFS ALBATROSS/ICD DADRI | J15: 1101.81
A16: NATURAL HONEY | B16: 207.97 | E16: Inland ICD / CFS | F16: 8554.29 | G16: 0.29601596 | I16: CHENNAI SEA | J16: 668.99
A17: POULTRY PRODUCTS | B17: 103.71 | E17: Land Border / Rail | F17: 1951.22 | G17: 0.067520772 | I17: ICD CGML DADRI | J17: 625.89
A18: Fresh Fruits & Vegetables | B18: 1904.89 | E18: Sea Port | F18: 17382.58 | G18: 0.60151353 | I18: ICD SAMALKHA PANIPAT Haryana | J18: 709.44
A19: FRESH GRAPES | B19: 367.97 | E19: SEZ / EPZ | F19: 332.77 | G19: 0.011515302 | I19: ICD SONIPAT ICD | J19: 711.04
A20: FRESH MANGOES | B20: 53.99 | E20: Grand Total | F20: 28898.07 | G20: 1 | I20: KAKINADA SEA | J20: 1359.85
A21: FRESH ONIONS | B21: 397.23 | I21: KANDLA SEA SEA | J21: 1952.7
A22: OTHER FRESH FRUITS | B22: 722.64 | E22: Pivot_State. | I22: MUNDRA SEA | J22: 4993.32
A23: OTHER FRESH VEGETABLES | B23: 363.06 | E23: Row Labels | F23: Sum of 2025-26 Value (USD Mn) | G23: Share% | I23: NHAVA SHEVA SEA | J23: 5014.51
A24: Meat & Animal Products | B24: 5262.74 | E24: Andhra Pradesh | F24: 2135.11 | G24: 0.073884173 | I24: VISAKHAPATNAM SEA | J24: 761.92
A25: ANIMAL CASINGS | B25: 58.9 | E25: Assam | F25: 32.54 | G25: 0.0011260268 | I25: Grand Total | J25: 17899.47
A26: BUFFALO MEAT | B26: 5098.84 | E26: Bihar | F26: 351.7 | G26: 0.012170363
A27: OTHER MEAT | B27: 0 | E27: Chhattisgarh | F27: 8.35 | G27: 0.00028894663
A28: PROCESSED MEAT | B28: 1.43 | E28: Delhi | F28: 241.75 | G28: 0.0083656106
A29: SHEEP/GOAT MEAT | B29: 103.57 | E29: Goa | F29: 16.19 | G29: 0.00056024503
A30: Nuts & Oilseeds | B30: 1129.89 | E30: Gujarat | F30: 8112.64 | G30: 0.28073293
A31: Cashew Kernel | B31: 265.04 | E31: Haryana | F31: 2205.68 | G31: 0.076326204
A32: Cashew Nuts Fresh/Dried In Shell | B32: 114.11 | E32: Himachal Pradesh | F32: 0.08 | G32: 2.768351e-06
A33: Cashew Nuts Roasted/Value Added | B33: 24.59 | E33: Karnataka | F33: 487.25 | G33: 0.016860988
A34: Cashew shell liquid (CNSL) | B34: 26.76 | E34: Kerala | F34: 678.44 | G34: 0.023477
A35: GROUNDNUTS | B35: 690.93 | E35: Madhya Pradesh | F35: 409.39 | G35: 0.01416669
A36: WALNUTS | B36: 8.46 | E36: Maharashtra | F36: 6056.28 | G36: 0.20957386
A37: Others | B37: 850.31 | E37: Meghalaya | F37: 0.25 | G37: 8.6510968e-06
... A49: MANGO PULP | B49: 68.42 | E49: Grand Total | F49: 28898.07 | G49: 1
A50: MISCELLANEOUS PREPARATIONS | B50: 1493.71
A51: PROCESSED FRUITS, JUICES & NUTS | B51: 662.83
...
